Workbook

Sheet Report
L2: DASHBOARD EXECUTIVO - PROJETO | M2: =gp_Cabecalhos!B1 | U2: Gerente do Projeto | AB2: Data da extração: | AC2: =gp_Cabecalhos!B7 | AQ2: DASHBOARD EXECUTIVO - SPRINT | AR2: =gp_Cabecalhos!B1 | AZ2: Gerente do Projeto | BA2: =gp_Cabecalhos!B2 | BG2: Data da extração: | BH2: =gp_Cabecalhos!B7
U3: Linkedin: | V3: =gp_Cabecalhos!B3 | AZ3: Linkedin: | BA3: =gp_Cabecalhos!B3
B5: DADOS GERENCIAIS DO PROJETO | D5: PRODUCT GOAL (Meta/Objetivo do produto) | AG5: DADOS DA SPRINT | AI5: SPRINT GOAL (Meta/Objetivo da sprint)
D6: =gp_Cabecalhos!B4 | AI6: =gp_Cabecalhos!B5
G9: REQUISITOS | R9: =AVERAGE(V9:AC9) | U9: REQUISITOS
D10: ROADMAP DO PROJETO | AI10: =xKPI!B1 | AK10: =xKPI!B2 | AM10: =xKPI!B3 | AO10: =xKPI!B4 | AQ10: =xKPI!B5 | AS10: =xKPI!B6 | AU10: =xKPI!B7 | AW10: =xKPI!B8 | AY10: =xKPI!B9 | BA10: =xKPI!B10 | BC10: =xKPI!B11 | BE10: =xKPI!B12 | BG10: =xKPI!B13
G11: UX/UI (MOBILE) | R11: =AVERAGE(V11:AC11) | U11: UX/UI (MOBILE) | AI11: =xKPI!A1 | AK11: =xKPI!A2 | AM11: =xKPI!A3 | AO11: =xKPI!A4 | AQ11: =xKPI!A5 | AS11: =xKPI!A6 | AU11: =xKPI!A7 | AW11: =xKPI!A8 | AY11: =xKPI!A9 | BA11: =xKPI!A10 | BC11: =xKPI!A11 | BE11: =xKPI!A12 | BG11: =xKPI!A13
G12: DEV FRONT (DESKTOP) | R12: =AVERAGE(V12:AC12) | U12: DEV FRONT (DESKTOP)
G13: DEV FRONT (MOBILE) | R13: =AVERAGE(V13:AC13) | U13: DEV FRONT (MOBILE)
G14: DEV BACK | R14: =AVERAGE(V14:AC14) | U14: DEV BACK
G15: DEV BANCO DE DADOS | R15: =AVERAGE(V15:AC15) | U15: DEV BANCO DE DADOS
G16: DEV BI | R16: =AVERAGE(V16:AC16) | U16: DEV BI
G17: TESTE (possíveis no prazo da sprint) | R17: =AVERAGE(V17:AC17) | U17: TESTE (possíveis no prazo da sprint)
G18: ARQUITETURA | R18: =AVERAGE(V18:AC18) | U18: ARQUITETURA
G19: Mensuração (maior esforço individual) | R19: =AVERAGE(V19:AC19) | U19: Mensuração (maior esforço individual)
G20: Mensuracao soma total esforço por HU | R20: =AVERAGE(V20:AC20) | U20: Mensuracao soma total esforço por HU
R21: =AVERAGE(V21:AC21) | U21: Quantidade de Histórias de Usuário (HU)
D33: HISTORICO DE PONTUAÇÃO DO PROJETO POR PERFIL
D35: Média de storypoints por perfil | G35: =gp_Plann_Projeto!A1 | H35: =gp_Plann_Projeto!B1 | I35: =gp_Plann_Projeto!C1 | J35: =gp_Plann_Projeto!D1 | K35: =gp_Plann_Projeto!E1 | L35: =gp_Plann_Projeto!F1 | M35: =gp_Plann_Projeto!G1 | N35: =gp_Plann_Projeto!H1 | O35: =gp_Plann_Projeto!I1
D36: =AVERAGE(H36:O36) | G36: =gp_Plann_Projeto!A2 | H36: =gp_Plann_Projeto!B2 | I36: =gp_Plann_Projeto!C2 | J36: =gp_Plann_Projeto!D2 | K36: =gp_Plann_Projeto!E2 | L36: =gp_Plann_Projeto!F2 | M36: =gp_Plann_Projeto!G2 | N36: =gp_Plann_Projeto!H2 | ... S36: =gp_Plann_Projeto!M2
D37: =AVERAGE(H37:O37) | G37: =gp_Plann_Projeto!A3 | H37: =gp_Plann_Projeto!B3 | I37: =gp_Plann_Projeto!C3 | J37: =gp_Plann_Projeto!D3 | K37: =gp_Plann_Projeto!E3 | L37: =gp_Plann_Projeto!F3 | M37: =gp_Plann_Projeto!G3 | N37: =gp_Plann_Projeto!H3 | ... S37: =gp_Plann_Projeto!M3
D38: =AVERAGE(H38:O38) | G38: =gp_Plann_Projeto!A4 | H38: =gp_Plann_Projeto!B4 | I38: =gp_Plann_Projeto!C4 | J38: =gp_Plann_Projeto!D4 | K38: =gp_Plann_Projeto!E4 | L38: =gp_Plann_Projeto!F4 | M38: =gp_Plann_Projeto!G4 | N38: =gp_Plann_Projeto!H4 | ... S38: =gp_Plann_Projeto!M4
D39: =AVERAGE(H39:O39) | G39: =gp_Plann_Projeto!A5 | H39: =gp_Plann_Projeto!B5 | I39: =gp_Plann_Projeto!C5 | J39: =gp_Plann_Projeto!D5 | K39: =gp_Plann_Projeto!E5 | L39: =gp_Plann_Projeto!F5 | M39: =gp_Plann_Projeto!G5 | N39: =gp_Plann_Projeto!H5 | ... S39: =gp_Plann_Projeto!M5
D40: =AVERAGE(H40:O40) | G40: =gp_Plann_Projeto!A6 | H40: =gp_Plann_Projeto!B6 | I40: =gp_Plann_Projeto!C6 | J40: =gp_Plann_Projeto!D6 | K40: =gp_Plann_Projeto!E6 | L40: =gp_Plann_Projeto!F6 | M40: =gp_Plann_Projeto!G6 | N40: =gp_Plann_Projeto!H6 | ... S40: =gp_Plann_Projeto!M6
D41: =AVERAGE(H41:O41) | G41: =gp_Plann_Projeto!A7 | H41: =gp_Plann_Projeto!B7 | I41: =gp_Plann_Projeto!C7 | J41: =gp_Plann_Projeto!D7 | K41: =gp_Plann_Projeto!E7 | L41: =gp_Plann_Projeto!F7 | M41: =gp_Plann_Projeto!G7 | N41: =gp_Plann_Projeto!H7 | ... S41: =gp_Plann_Projeto!M7
D42: =AVERAGE(H42:O42) | G42: =gp_Plann_Projeto!A8 | H42: =gp_Plann_Projeto!B8 | I42: =gp_Plann_Projeto!C8 | J42: =gp_Plann_Projeto!D8 | K42: =gp_Plann_Projeto!E8 | L42: =gp_Plann_Projeto!F8 | M42: =gp_Plann_Projeto!G8 | N42: =gp_Plann_Projeto!H8 | ... S42: =gp_Plann_Projeto!M8
D43: =AVERAGE(H43:O43) | G43: =gp_Plann_Projeto!A9 | H43: =gp_Plann_Projeto!B9 | I43: =gp_Plann_Projeto!C9 | J43: =gp_Plann_Projeto!D9 | K43: =gp_Plann_Projeto!E9 | L43: =gp_Plann_Projeto!F9 | M43: =gp_Plann_Projeto!G9 | N43: =gp_Plann_Projeto!H9 | ... S43: =gp_Plann_Projeto!M9
D44: =AVERAGE(H44:O44) | G44: =gp_Plann_Projeto!A10 | H44: =gp_Plann_Projeto!B10 | I44: =gp_Plann_Projeto!C10 | J44: =gp_Plann_Projeto!D10 | K44: =gp_Plann_Projeto!E10 | L44: =gp_Plann_Projeto!F10 | M44: =gp_Plann_Projeto!G10 | N44: =gp_Plann_Projeto!H10 | ... S44: =gp_Plann_Projeto!M10
D45: =AVERAGE(H45:O45) | G45: =gp_Plann_Projeto!A11 | H45: =gp_Plann_Projeto!B11 | I45: =gp_Plann_Projeto!C11 | J45: =gp_Plann_Projeto!D11 | K45: =gp_Plann_Projeto!E11 | L45: =gp_Plann_Projeto!F11 | M45: =gp_Plann_Projeto!G11 | N45: =gp_Plann_Projeto!H11 | ... S45: =gp_Plann_Projeto!M11
D46: =AVERAGE(H46:O46) | G46: =gp_Plann_Projeto!A12 | H46: =gp_Plann_Projeto!B12 | I46: =gp_Plann_Projeto!C12 | J46: =gp_Plann_Projeto!D12 | K46: =gp_Plann_Projeto!E12 | L46: =gp_Plann_Projeto!F12 | M46: =gp_Plann_Projeto!G12 | N46: =gp_Plann_Projeto!H12 | ... S46: =gp_Plann_Projeto!M12
D47: =AVERAGE(H47:O47) | G47: Mensuração (maior esforço individual) | H47: N/A | I47: N/A | J47: N/A | K47: N/A | L47: 40 | M47: 40 | N47: 48 | O47: 48 | P47: 0 | Q47: 0 | R47: 0 | S47: 0
D48: =AVERAGE(H48:O48) | G48: Throughput - Qtd Storypoints | H48: N/A | I48: N/A | J48: N/A | K48: =SUM(K36:K46) | L48: =SUM(L36:L46) | M48: =SUM(M36:M46) | N48: =SUM(N36:N46) | O48: =SUM(O36:O46) | P48: =SUM(P36:P46) | Q48: =SUM(Q36:Q46) | R48: =SUM(R36:R46) | S48: =SUM(S36:S46)
D49: =AVERAGE(H49:O49) | G49: Throughput - Qtd de Tarefas/Cards | H49: N/A | I49: N/A | J49: 160 | K49: 40 | L49: 30 | M49: 50 | N49: 64 | O49: 53 | P49: 0 | Q49: 0 | R49: 0 | S49: 0
D50: =AVERAGE(H50:O50) | G50: Qtd de Histórias de Usuário (HU) | H50: N/A | I50: N/A | J50: N/A | K50: 1 | L50: 5 | M50: 5 | N50: 6 | O50: 6 | P50: 0 | Q50: 0 | R50: 0 | S50: 0
D52: PLANEJAMENTO DA SPRINT ATUAL
G53: PRIORIDADE | H53: 1 | I53: 2 | J53: 3 | K53: 4 | L53: 5 | M53: 6 | N53: 7 | O53: 8 | P53: 9 | Q53: 10 | R53: 11 | S53: 12
D54: TOTAL de storypoints por perfil | G54: =gp_Plann_Sprint!A1 | H54: =gp_Plann_Sprint!B1 | I54: =gp_Plann_Sprint!C1 | J54: =gp_Plann_Sprint!D1 | K54: =gp_Plann_Sprint!E1 | L54: =gp_Plann_Sprint!F1 | M54: =gp_Plann_Sprint!G1 | N54: =gp_Plann_Sprint!H1 | ... S54: =gp_Plann_Sprint!M1
D55: =SUM(H55:P55) | G55: =gp_Plann_Sprint!A2 | H55: =gp_Plann_Sprint!B2 | I55: =gp_Plann_Sprint!C2 | J55: =gp_Plann_Sprint!D2 | K55: =gp_Plann_Sprint!E2 | L55: =gp_Plann_Sprint!F2 | M55: =gp_Plann_Sprint!G2 | N55: =gp_Plann_Sprint!H2 | ... S55: =gp_Plann_Sprint!M2
D56: =SUM(H56:P56) | G56: =gp_Plann_Sprint!A3 | H56: =gp_Plann_Sprint!B3 | I56: =gp_Plann_Sprint!C3 | J56: =gp_Plann_Sprint!D3 | K56: =gp_Plann_Sprint!E3 | L56: =gp_Plann_Sprint!F3 | M56: =gp_Plann_Sprint!G3 | N56: =gp_Plann_Sprint!H3 | ... S56: =gp_Plann_Sprint!M3
D57: =SUM(H57:P57) | G57: =gp_Plann_Sprint!A4 | H57: =gp_Plann_Sprint!B4 | I57: =gp_Plann_Sprint!C4 | J57: =gp_Plann_Sprint!D4 | K57: =gp_Plann_Sprint!E4 | L57: =gp_Plann_Sprint!F4 | M57: =gp_Plann_Sprint!G4 | N57: =gp_Plann_Sprint!H4 | ... S57: =gp_Plann_Sprint!M4
...

Sheet gp_Plann_Projeto

Sheet gp_Plann_Sprint
A1: ID ou DESCRIÇÃO DO ITEM
A2: PO (DOCS, LINKS, LEIS, ETC.)
A3: REQUISITOS
A4: UX/UI (DESKTOP)
A5: UX/UI (MOBILE)
A6: BENCHMARK COMPONENTES - DEV
A7: CONSTRUCAO COMPONENTES - DEV
A8: TESTES- DEV
A9: REGISTRO e PUBLICAÇÃO (Storybook) - DEV

Sheet gp_Cabecalhos
A1: PROJETO
A2: NOME DO GERENTE DO PROJETO
A3: link para LINKEDIN DO GERENTE DO PROJETO
A4: PRODUCT GOAL (OBJETIVO DO PROJETO)
A5: SPRINT GOAL (OBJETIVO DA SPRINT)
A6: LINK ARQUIVO BASE / PLANO
A7: DATA DA EXTRACAO DOS DADOS

Sheet gp_Disponibilidade
B1: Empregador | C1: Envolvimento no Projeto
A2: =COUNTIF(B8:B96,B2) | B2: Spezi | C2: =A2/A5
A3: =COUNTIF(B8:B96,B3) | B3: SPGG/STI | C3: =A3/A5
A4: =COUNTIF(B8:B96,B4) | B4: G4F | C4: =A4/A5
A5: =COUNTA(A8:A96) | B5: TODOS | C5: =SUM(C2:C4)

Sheet gp_Transversalidade
A1: NOME | B1: FUNÇÃO | C1: SQUAD | D1: INTERVALO | E1: coluna

Sheet gp_Roadmap
A1: Marco | B1: Posição

Sheet xKPI

Sheet xResponsaveis

Sheet xRotulos

Sheet xBurndownStorypoints

Sheet xBurndownTarefas

Sheet xBurndownHU

Sheet xHU_inOut

Sheet xAreas

Sheet xEsforcoHU

Sheet xHistograma

Sheet xHistograma2

Sheet xDispersaoTarefas

Sheet xWIP

Sheet xCFD

Sheet xCTS

Sheet xHUs
